Workbook

Sheet MS New
A1: ACCOUNT BALANCES
A2: Account Name | B2: BBF | C2: Receipts | D2: Payments | E2: Tfr IN | F2: Tfr Out | G2: Net
A3: Shah Mir | B3: -8480 | C3: =SUMIF(Income!H:H,'MS New'!A3,Income!G:G) -> 2650 | D3: =SUMIF(Expense!F:F,'MS New'!A3,Expense!E:E) -> 25170 | E3: =SUMIF(tfr!$E:$E,'MS New'!A3,tfr!$C:$C) -> 30000 | F3: =SUMIF(tfr!D:D,'MS New'!A3,tfr!C:C) -> 0 | G3: =+B3+C3-D3+E3-F3 -> -1000
A4: Agha Guloon | B4: 4511 | C4: =SUMIF(Income!H:H,'MS New'!A4,Income!G:G) -> 0 | D4: =SUMIF(Expense!F:F,'MS New'!A4,Expense!E:E) -> 280500 | E4: =SUMIF(tfr!$E:$E,'MS New'!A4,tfr!$C:$C) -> 302000 | F4: =SUMIF(tfr!D:D,'MS New'!A4,tfr!C:C) -> 26000 | G4: =+B4+C4-D4+E4-F4 -> 11
A5: Abdul Abbas | B5: 4238 | C5: =SUMIF(Income!H:H,'MS New'!A5,Income!G:G) -> 0 | D5: =SUMIF(Expense!F:F,'MS New'!A5,Expense!E:E) -> 2461 | E5: =SUMIF(tfr!$E:$E,'MS New'!A5,tfr!$C:$C) -> 0 | F5: =SUMIF(tfr!D:D,'MS New'!A5,tfr!C:C) -> 4000 | G5: =+B5+C5-D5+E5-F5 -> -2223
A6: Principal Br1 | B6: 5350 | C6: =SUMIF(Income!H:H,'MS New'!A6,Income!G:G) -> 359150 | D6: =SUMIF(Expense!F:F,'MS New'!A6,Expense!E:E) -> 119200 | E6: =SUMIF(tfr!$E:$E,'MS New'!A6,tfr!$C:$C) -> 0 | F6: =SUMIF(tfr!D:D,'MS New'!A6,tfr!C:C) -> 237850 | G6: =+B6+C6-D6+E6-F6 -> 7450
A7: Fund Br1 | B7: 1715 | C7: =SUMIF(Income!H:H,'MS New'!A7,Income!G:G) -> 15820 | D7: =SUMIF(Expense!F:F,'MS New'!A7,Expense!E:E) -> 15665 | E7: =SUMIF(tfr!$E:$E,'MS New'!A7,tfr!$C:$C) -> 5350 | F7: =SUMIF(tfr!D:D,'MS New'!A7,tfr!C:C) -> 0 | G7: =+B7+C7-D7+E7-F7 -> 7220
A8: Principal Br2 | B8: 0 | C8: =SUMIF(Income!H:H,'MS New'!A8,Income!G:G) -> 228970 | D8: =SUMIF(Expense!F:F,'MS New'!A8,Expense!E:E) -> 122200 | E8: =SUMIF(tfr!$E:$E,'MS New'!A8,tfr!$C:$C) -> 0 | F8: =SUMIF(tfr!D:D,'MS New'!A8,tfr!C:C) -> 84550 | G8: =+B8+C8-D8+E8-F8 -> 22220
A9: Fund Br2 | B9: -3840 | C9: =SUMIF(Income!H:H,'MS New'!A9,Income!G:G) -> 0 | D9: =SUMIF(Expense!F:F,'MS New'!A9,Expense!E:E) -> 0 | E9: =SUMIF(tfr!$E:$E,'MS New'!A9,tfr!$C:$C) -> 15050 | F9: =SUMIF(tfr!D:D,'MS New'!A9,tfr!C:C) -> 0 | G9: =+B9+C9-D9+E9-F9 -> 11210
A11: Account Name | B11: Amount
A12: Shah Mir | B12: =+G3 -> -1000
A13: Agha Guloon | B13: =+G4 -> 11
A14: Abdul Abbas | B14: =+G5 -> -2223
A15: Principal Br1 | B15: =+G6 -> 7450 | E15: =2086+1546 -> 3632
A16: Fund Br1 | B16: =+G7 -> 7220 | E16: =40-15 -> 25
A17: Principal Br2 | B17: =+G8 -> 22220 | D17: =22600-Table1[[#This Row],[Amount]] -> 380 | E17: =2829+3733 -> 6562
A18: Fund Br2 | B18: =+G9 -> 11210 | D18: =5590+1180+900+1950 -> 9620
A19: Total | B19: =SUM(B12:B18) -> 44888
A23: Branch | B23: Class | C23: Total Fee | D23: Received Fee | E23: Balance Fee | F23: Collection Rate (%)
A24: Branch 1 | B24: PG | C24: =SUMIFS(Income!F:F,Income!A:A,'MS New'!A24,Income!B:B,'MS New'!B24) -> 36150 | D24: =SUMIFS(Income!G:G,Income!A:A,'MS New'!A24,Income!B:B,'MS New'!B24) -> 34400 | E24: =SUMIFS(Income!I:I, Income!A:A, 'MS New'!A24, Income!B:B, 'MS New'!B24, Income!I:I, ">0") -> 1750 | F24: =+D24/C24 -> 0.95159059
A25: Branch 1 | B25: J1 | C25: =SUMIFS(Income!F:F,Income!A:A,'MS New'!A25,Income!B:B,'MS New'!B25) -> 41400 | D25: =SUMIFS(Income!G:G,Income!A:A,'MS New'!A25,Income!B:B,'MS New'!B25) -> 41400 | E25: =SUMIFS(Income!I:I, Income!A:A, 'MS New'!A25, Income!B:B, 'MS New'!B25, Income!I:I, ">0") -> 0 | F25: =+D25/C25 -> 1
A26: Branch 1 | B26: J2 | C26: =SUMIFS(Income!F:F,Income!A:A,'MS New'!A26,Income!B:B,'MS New'!B26) -> 38000 | D26: =SUMIFS(Income!G:G,Income!A:A,'MS New'!A26,Income!B:B,'MS New'!B26) -> 38000 | E26: =SUMIFS(Income!I:I, Income!A:A, 'MS New'!A26, Income!B:B, 'MS New'!B26, Income!I:I, ">0") -> 0 | F26: =+D26/C26 -> 1
A27: Branch 1 | B27: Cl1A | C27: =SUMIFS(Income!F:F,Income!A:A,'MS New'!A27,Income!B:B,'MS New'!B27) -> 34200 | D27: =SUMIFS(Income!G:G,Income!A:A,'MS New'!A27,Income!B:B,'MS New'!B27) -> 34200 | E27: =SUMIFS(Income!I:I, Income!A:A, 'MS New'!A27, Income!B:B, 'MS New'!B27, Income!I:I, ">0") -> 0 | F27: =+D27/C27 -> 1
A28: Branch 1 | B28: Cl1B | C28: =SUMIFS(Income!F:F,Income!A:A,'MS New'!A28,Income!B:B,'MS New'!B28) -> 41050 | D28: =SUMIFS(Income!G:G,Income!A:A,'MS New'!A28,Income!B:B,'MS New'!B28) -> 41050 | E28: =SUMIFS(Income!I:I, Income!A:A, 'MS New'!A28, Income!B:B, 'MS New'!B28, Income!I:I, ">0") -> 0 | F28: =+D28/C28 -> 1
A29: Branch 1 | B29: Cl2 | C29: =SUMIFS(Income!F:F,Income!A:A,'MS New'!A29,Income!B:B,'MS New'!B29) -> 55650 | D29: =SUMIFS(Income!G:G,Income!A:A,'MS New'!A29,Income!B:B,'MS New'!B29) -> 55650 | E29: =SUMIFS(Income!I:I, Income!A:A, 'MS New'!A29, Income!B:B, 'MS New'!B29, Income!I:I, ">0") -> 0 | F29: =+D29/C29 -> 1
A30: Branch 1 | B30: Cl3 | C30: =SUMIFS(Income!F:F,Income!A:A,'MS New'!A30,Income!B:B,'MS New'!B30) -> 43700 | D30: =SUMIFS(Income!G:G,Income!A:A,'MS New'!A30,Income!B:B,'MS New'!B30) -> 43700 | E30: =SUMIFS(Income!I:I, Income!A:A, 'MS New'!A30, Income!B:B, 'MS New'!B30, Income!I:I, ">0") -> 0 | F30: =+D30/C30 -> 1
A31: Branch 1 | B31: Cl4 | C31: =SUMIFS(Income!F:F,Income!A:A,'MS New'!A31,Income!B:B,'MS New'!B31) -> 36100 | D31: =SUMIFS(Income!G:G,Income!A:A,'MS New'!A31,Income!B:B,'MS New'!B31) -> 36100 | E31: =SUMIFS(Income!I:I, Income!A:A, 'MS New'!A31, Income!B:B, 'MS New'!B31, Income!I:I, ">0") -> 0 | F31: =+D31/C31 -> 1
A32: Branch 1 | B32: Cl5 | C32: =SUMIFS(Income!F:F,Income!A:A,'MS New'!A32,Income!B:B,'MS New'!B32) -> 34650 | D32: =SUMIFS(Income!G:G,Income!A:A,'MS New'!A32,Income!B:B,'MS New'!B32) -> 34650 | E32: =SUMIFS(Income!I:I, Income!A:A, 'MS New'!A32, Income!B:B, 'MS New'!B32, Income!I:I, ">0") -> 0 | F32: =+D32/C32 -> 1
A33: Branch 1 | B33: Copies | D33: =SUMIFS(Income!G:G,Income!A:A,'MS New'!A33,Income!B:B,'MS New'!B33) -> 13740
A34: Branch 1 | B34: Total | C34: =SUM(C24:C32) -> 360900 | D34: =SUM(D24:D33) -> 372890 | E34: =SUM(E24:E32) -> 1750
A35: Branch | B35: Class | C35: Total Fee | D35: Received Fee | E35: Balance Fee | F35: Collection Rate (%)
A36: Branch 2 | B36: PG | C36: =SUMIFS(Income!F:F,Income!A:A,'MS New'!A36,Income!B:B,'MS New'!B36) -> 45850 | D36: =SUMIFS(Income!G:G,Income!A:A,'MS New'!A36,Income!B:B,'MS New'!B36) -> 45850 | E36: =SUMIFS(Income!I:I, Income!A:A, 'MS New'!A36, Income!B:B, 'MS New'!B36, Income!I:I, ">0") -> 0 | F36: =+D36/C36 -> 1
A37: Branch 2 | B37: J1 | C37: =SUMIFS(Income!F:F,Income!A:A,'MS New'!A37,Income!B:B,'MS New'!B37) -> 38000 | D37: =SUMIFS(Income!G:G,Income!A:A,'MS New'!A37,Income!B:B,'MS New'!B37) -> 37000 | E37: =SUMIFS(Income!I:I, Income!A:A, 'MS New'!A37, Income!B:B, 'MS New'!B37, Income!I:I, ">0") -> 1000 | F37: =+D37/C37 -> 0.97368421
A38: Branch 2 | B38: J2 | C38: =SUMIFS(Income!F:F,Income!A:A,'MS New'!A38,Income!B:B,'MS New'!B38) -> 31550 | D38: =SUMIFS(Income!G:G,Income!A:A,'MS New'!A38,Income!B:B,'MS New'!B38) -> 31550 | E38: =SUMIFS(Income!I:I, Income!A:A, 'MS New'!A38, Income!B:B, 'MS New'!B38, Income!I:I, ">0") -> 0 | F38: =+D38/C38 -> 1
A39: Branch 2 | B39: Cl1A | C39: =SUMIFS(Income!F:F,Income!A:A,'MS New'!A39,Income!B:B,'MS New'!B39) -> 26350 | D39: =SUMIFS(Income!G:G,Income!A:A,'MS New'!A39,Income!B:B,'MS New'!B39) -> 26350 | E39: =SUMIFS(Income!I:I, Income!A:A, 'MS New'!A39, Income!B:B, 'MS New'!B39, Income!I:I, ">0") -> 0 | F39: =+D39/C39 -> 1
A40: Branch 2 | B40: Cl2 | C40: =SUMIFS(Income!F:F,Income!A:A,'MS New'!A40,Income!B:B,'MS New'!B40) -> 26400 | D40: =SUMIFS(Income!G:G,Income!A:A,'MS New'!A40,Income!B:B,'MS New'!B40) -> 26400 | E40: =SUMIFS(Income!I:I, Income!A:A, 'MS New'!A40, Income!B:B, 'MS New'!B40, Income!I:I, ">0") -> 0 | F40: =+D40/C40 -> 1
A41: Branch 2 | B41: Cl3 | C41: =SUMIFS(Income!F:F,Income!A:A,'MS New'!A41,Income!B:B,'MS New'!B41) -> 16650 | D41: =SUMIFS(Income!G:G,Income!A:A,'MS New'!A41,Income!B:B,'MS New'!B41) -> 18650 | E41: =SUMIFS(Income!I:I, Income!A:A, 'MS New'!A41, Income!B:B, 'MS New'!B41, Income!I:I, ">0") -> 0 | F41: =+D41/C41 -> 1.1201201
A42: Branch 2 | B42: Cl4 | C42: =SUMIFS(Income!F:F,Income!A:A,'MS New'!A42,Income!B:B,'MS New'!B42) -> 18550 | D42: =SUMIFS(Income!G:G,Income!A:A,'MS New'!A42,Income!B:B,'MS New'!B42) -> 18550 | E42: =SUMIFS(Income!I:I, Income!A:A, 'MS New'!A42, Income!B:B, 'MS New'!B42, Income!I:I, ">0") -> 0 | F42: =+D42/C42 -> 1
A43: Branch 2 | B43: Cl5 | C43: =SUMIFS(Income!F:F,Income!A:A,'MS New'!A43,Income!B:B,'MS New'!B43) -> 20500 | D43: =SUMIFS(Income!G:G,Income!A:A,'MS New'!A43,Income!B:B,'MS New'!B43) -> 20500 | E43: =SUMIFS(Income!I:I, Income!A:A, 'MS New'!A43, Income!B:B, 'MS New'!B43, Income!I:I, ">0") -> 0 | F43: =+D43/C43 -> 1
A44: Branch 2 | B44: Copies | D44: =SUMIFS(Income!G:G,Income!A:A,'MS New'!A44,Income!B:B,'MS New'!B44) -> 6770
...

Sheet tfr
A1: Ser | B1: Date | C1: Amount | D1: From Account | E1: To Account
A2: 1 | B2: 46022 | C2: 5350 | D2: Principal Br1 | E2: Fund Br1
A3: 2 | B3: 46022 | C3: =5000+50 -> 5050 | D3: Principal Br2 | E3: Fund Br2
A4: 3 | B4: 46022 | C4: 69500 | D4: Principal Br2 | E4: Agha Guloon
A5: 4 | B5: 46022 | C5: 232500 | D5: Principal Br1 | E5: Agha Guloon
C6: 26000 | D6: Agha Guloon | E6: Shah Mir
C7: 4000 | D7: Abdul Abbas | E7: Shah Mir
B8: 46051 | C8: 10000 | D8: Principal Br2 | E8: Fund Br2

Sheet Income
A1: Branch | B1: Class | C1: Roll No | D1: Name | E1: Monthly Fee | F1: Total Payable | G1: Amount Received | H1: Account Received | I1: Balance | J1: Status | M1: Branch | N1: Class | O1: Account
A2: Branch 1 | B2: PG | C2: 1 | D2: Eshaal Fatima | E2: 900 | F2: 900 | G2: 900 | H2: Principal Br1 | I2: =F2-G2 -> 0 | M2: Branch 1 | N2: PG | O2: Shah Mir
A3: Branch 1 | B3: PG | C3: 2 | D3: Nida Shirin | E3: 900 | F3: 900 | G3: 900 | H3: Principal Br1 | I3: =F3-G3 -> 0 | M3: Branch 2 | N3: J1 | O3: Agha Guloon
A4: Branch 1 | B4: PG | C4: 3 | D4: Tufail Abbas | E4: 1750 | F4: 1750 | G4: 1750 | H4: Principal Br1 | I4: =F4-G4 -> 0 | N4: J2 | O4: Abdul Abbas
A5: Branch 1 | B5: PG | C5: 4 | D5: Zimal | E5: 900 | F5: 900 | G5: 900 | H5: Principal Br1 | I5: =F5-G5 -> 0 | N5: Cl1A | O5: Principal Br1
A6: Branch 1 | B6: PG | C6: 5 | D6: Sughra Batool | E6: 1750 | F6: 1750 | G6: 1750 | H6: Principal Br1 | I6: =F6-G6 -> 0 | N6: Cl1B | O6: Principal Br2
A7: Branch 1 | B7: PG | C7: 6 | D7: Naseer | E7: 0 | F7: 0 | G7: 0 | H7: Principal Br1 | I7: =F7-G7 -> 0 | N7: Cl2 | O7: Fund Br1
A8: Branch 1 | B8: PG | C8: 7 | D8: Wirda Zahra | E8: 0 | F8: 0 | G8: 0 | H8: Principal Br1 | I8: =F8-G8 -> 0 | N8: Cl3 | O8: Fund Br2
A9: Branch 1 | B9: PG | C9: 8 | D9: Muhammad Aoun | E9: 900 | F9: 900 | G9: 900 | H9: Principal Br1 | I9: =F9-G9 -> 0 | N9: Cl4
A10: Branch 1 | B10: PG | C10: 9 | D10: Fadak Zahra | E10: 1750 | F10: 1750 | G10: 1750 | H10: Principal Br1 | I10: =F10-G10 -> 0 | N10: Cl5
A11: Branch 1 | B11: PG | C11: 10 | D11: Maryam Batool | E11: 1750 | F11: 1750 | G11: 1750 | H11: Principal Br1 | I11: =F11-G11 -> 0
A12: Branch 1 | B12: PG | C12: 12 | D12: Kubra Zahra | E12: 900 | F12: 900 | G12: 900 | H12: Principal Br1 | I12: =F12-G12 -> 0
A13: Branch 1 | B13: PG | C13: 13 | D13: M.Shuja Abbas | E13: 1750 | F13: 1750 | G13: 1750 | H13: Principal Br1 | I13: =F13-G13 -> 0
A14: Branch 1 | B14: PG | C14: 14 | D14: Anshra | E14: 900 | F14: 900 | G14: 900 | H14: Principal Br1 | I14: =F14-G14 -> 0
A15: Branch 1 | B15: PG | C15: 15 | D15: Muhammad Safi Raza | E15: 1750 | F15: 1750 | G15: 1750 | H15: Principal Br1 | I15: =F15-G15 -> 0
A16: Branch 1 | B16: PG | C16: 16 | D16: Amna Batool | E16: 1750 | F16: 1750 | G16: 1750 | H16: Principal Br1 | I16: =F16-G16 -> 0
A17: Branch 1 | B17: PG | C17: 17 | D17: Tawasal Zahra | E17: 1750 | F17: 1750 | G17: 1750 | H17: Principal Br1 | I17: =F17-G17 -> 0
A18: Branch 1 | B18: PG | C18: 18 | D18: Ashal Abbas | E18: 1750 | F18: 1750 | G18: 1750 | H18: Principal Br1 | I18: =F18-G18 -> 0
A19: Branch 1 | B19: PG | C19: 19 | D19: M Hannan Ali | E19: 900 | F19: 900 | G19: 900 | H19: Principal Br1 | I19: =F19-G19 -> 0
A20: Branch 1 | B20: PG | C20: 20 | D20: M Hilal | E20: 1750 | F20: 1750 | G20: 1750 | H20: Principal Br1 | I20: =F20-G20 -> 0
A21: Branch 1 | B21: PG | C21: 21 | D21: Hussain Abbas | E21: 1750 | F21: 1750 | G21: 1750 | H21: Principal Br1 | I21: =F21-G21 -> 0
A22: Branch 1 | B22: PG | C22: 22 | D22: Wajdan Hussain | E22: 1750 | F22: 1750 | G22: 1750 | H22: Principal Br1 | I22: =F22-G22 -> 0
... A31: Branch 1 | B31: PG | C31: 31 | D31: Farhan Raza | E31: 900 | F31: 900 | G31: 900 | H31: Principal Br1 | I31: =F31-G31 -> 0
A32: Branch 1 | B32: PG | C32: 32 | D32: Adeel Raza | E32: 1750 | F32: 1750 | H32: Principal Br1 | I32: =F32-G32 -> 1750
A33: Branch 1 | B33: J1 | C33: 1 | D33: Taimur Hussain | E33: 900 | F33: 900 | G33: 900 | H33: Principal Br1 | I33: =F33-G33 -> 0
A34: Branch 1 | B34: J1 | C34: 2 | D34: Maham | E34: 900 | F34: 900 | G34: 900 | H34: Principal Br1 | I34: =F34-G34 -> 0
A35: Branch 1 | B35: J1 | C35: 3 | D35: Abeeha Batool | E35: 1750 | F35: 1750 | G35: 1750 | H35: Principal Br1 | I35: =F35-G35 -> 0
A36: Branch 1 | B36: J1 | C36: 4 | D36: Danyal Haider | E36: 1750 | F36: 1750 | G36: 1750 | H36: Principal Br1 | I36: =F36-G36 -> 0
A37: Branch 1 | B37: J1 | C37: 5 | D37: Hadi Mustafa | E37: 900 | F37: 900 | G37: 900 | H37: Principal Br1 | I37: =F37-G37 -> 0
A38: Branch 1 | B38: J1 | C38: 6 | D38: Wajihullah hassan | E38: 1750 | F38: 1750 | G38: 1750 | H38: Principal Br1 | I38: =F38-G38 -> 0
A39: Branch 1 | B39: J1 | C39: 7 | D39: Muhammad jasim Raza | E39: 900 | F39: 900 | G39: 900 | H39: Principal Br1 | I39: =F39-G39 -> 0
A40: Branch 1 | B40: J1 | C40: 8 | D40: Kiyyan Abbas | E40: 1750 | F40: 1750 | G40: 1750 | H40: Principal Br1 | I40: =F40-G40 -> 0
A41: Branch 1 | B41: J1 | C41: 9 | D41: M Rahim | E41: 900 | F41: 900 | G41: 900 | H41: Principal Br1 | I41: =F41-G41 -> 0
A42: Branch 1 | B42: J1 | C42: 10 | D42: M hadi | E42: 1750 | F42: 1750 | G42: 1750 | H42: Principal Br1 | I42: =F42-G42 -> 0
A43: Branch 1 | B43: J1 | C43: 11 | D43: Sadiq Haider | E43: 1750 | F43: 1750 | G43: 1750 | H43: Principal Br1 | I43: =F43-G43 -> 0
A44: Branch 1 | B44: J1 | C44: 12 | D44: Sabir Hussain | E44: 1750 | F44: 1750 | G44: 1750 | H44: Principal Br1 | I44: =F44-G44 -> 0
... A98: Branch 1 | B98: Cl1A | C98: 7 | D98: Muhammad Abideen | E98: 1950 | F98: 1950 | G98: 1950 | H98: Principal Br1 | I98: =F98-G98 -> 0
A99: Branch 1 | B99: Cl1A | C99: 8 | D99: Bibi Kinza | E99: 0 | F99: 0 | H99: Principal Br1 | I99: =F99-G99 -> 0
A100: Branch 1 | B100: Cl1A | C100: 9 | D100: Abeeha Abbas | E100: 1950 | F100: 1950 | G100: 1950 | H100: Principal Br1 | I100: =F100-G100 -> 0
A101: Branch 1 | B101: Cl1A | C101: 10 | D101: Owais Ali | E101: 1950 | F101: 1950 | G101: 1950 | H101: Principal Br1 | I101: =F101-G101 -> 0
...

Sheet Br1 Income Exp - AugSep 25
A1: June / July 2025 Ledger | N1: PAY ROLL - May Jun 2025
A2: Class Play Group | M2: revised | N2: S/No | O2: Name of Employee | P2: Post | Q2: Revised Pay | R2: Total May Jun 2025 | S2: Paid May June 2025 | T2: Bal
A3: Roll No | B3: Name | C3: Father Name | D3: Phone | E3: WA Number | F3: Monthly Fee | H3: Total Payable | I3: FEE | J3: Balance | N3: 1 | O3: Miss Annela Riaz | P3: Principal | Q3: 14500 | R3: =+Q3*2 -> 29000 | S3: 29000 | T3: =+R3-S3 -> 0 | V3: PAYMENTS | AA3: Paid By
A4: 1 | B4: Eshaal Fatima | F4: 1750 | H4: =+F4*2 -> 3500 | I4: 1800 | J4: =+H4-I4 -> 1700 | L4: =+F4*2+J4 -> 5200 | N4: 2 | O4: Miss Hanni Zahra | P4: Teacher | Q4: 8000 | R4: =+Q4*2 -> 16000 | S4: 16000 | T4: =+R4-S4 -> 0 | V4: a. | W4: Elec Bill | Y4: =1761+1763 -> 3524 | AA4: Abdul
A5: 2 | B5: Nida Shirin | F5: 900 | H5: =+F5*2 -> 1800 | I5: 1800 | J5: =+H5-I5 -> 0 | L5: =+F5*2+J5 -> 1800 | N5: 3 | O5: Miss Sofia | P5: Teacher | Q5: 8000 | R5: =+Q5*2 -> 16000 | S5: 16000 | T5: =+R5-S5 -> 0 | V5: b. | W5: PTCL | Y5: =3820+3870 -> 7690 | AA5: Abdul
A6: 3 | B6: Tufail Abbas | E6: 1750 | F6: 1750 | H6: =+F6*2 -> 3500 | J6: =+H6-I6 -> 3500 | L6: =+F6*2+J6 -> 7000 | N6: 4 | O6: Miss Shazia | P6: Teacher | Q6: 8000 | R6: =+Q6*2 -> 16000 | S6: 16000 | T6: =+R6-S6 -> 0 | V6: c. | W6: Rent | X6: Mar, April,May and Jun 25 | Y6: 41800 | AA6: Abdul
A7: 4 | B7: Zimal | F7: 900 | H7: =+F7*2 -> 1800 | I7: 1800 | J7: =+H7-I7 -> 0 | L7: =+F7*2+J7 -> 1800 | N7: 5 | O7: Miss Hina Mir | P7: Teacher | Q7: 9000 | R7: =+Q7*2 -> 18000 | S7: 18000 | T7: =+R7-S7 -> 0 | V7: d. | Z7: =+Y6/4 -> 10450
A8: 5 | B8: Sughra Batool | F8: 1750 | H8: =+F8*2 -> 3500 | I8: 3500 | J8: =+H8-I8 -> 0 | L8: =+F8*2+J8 -> 3500 | N8: 6 | O8: Miss Nazra Jabeen | P8: Teacher | Q8: 8000 | R8: =+Q8*2 -> 16000 | S8: 16000 | T8: =+R8-S8 -> 0
A9: 6 | B9: Naseer | F9: 0 | H9: =+F9*2 -> 0 | I9: 0 | J9: =+H9-I9 -> 0 | L9: =+F9*2+J9 -> 0 | N9: 7 | O9: Miss Areesha | P9: Teacher | Q9: 9000 | R9: =+Q9*2 -> 18000 | S9: 18000 | T9: =+R9-S9 -> 0 | V9: f.
A10: 7 | B10: Wirda Zahra | F10: 0 | H10: =+F10*2 -> 0 | I10: 0 | J10: =+H10-I10 -> 0 | L10: =+F10*2+J10 -> 0 | N10: 8 | O10: Miss Sukaina | P10: Teacher | Q10: 7500 | R10: =+Q10*2 -> 15000 | S10: 15000 | T10: =+R10-S10 -> 0 | V10: Total | Y10: =SUM(Y4:Y9) -> 53014
A11: 8 | B11: Muhammad Aoun | F11: 900 | H11: =+F11*2 -> 1800 | I11: 1800 | J11: =+H11-I11 -> 0 | L11: =+F11*2+J11 -> 1800 | N11: 9 | O11: Miss Noor Fatima | P11: Teacher | Q11: 5000 | R11: =+Q11*2 -> 10000 | S11: 10000 | T11: =+R11-S11 -> 0 | V11: Other Payments
A12: 9 | B12: Fadak Zahra | F12: 1750 | H12: =+F12*2 -> 3500 | I12: 3500 | J12: =+H12-I12 -> 0 | L12: =+F12*2+J12 -> 3500 | O12: Safina | P12: Teacher | Q12: 7000 | R12: =+Q12*2 -> 14000 | S12: 14000 | T12: =+R12-S12 -> 0 | V12: S/No | W12: Dated | X12: Category | Y12: Amount (Rs) | Z12: Items detail | AA12: Paid By
A13: 10 | B13: Maryam Batool | F13: 1750 | H13: =+F13*2 -> 3500 | I13: 3500 | J13: =+H13-I13 -> 0 | L13: =+F13*2+J13 -> 3500 | N13: 10 | O13: Yasmeen | P13: Ayya | Q13: 7500 | R13: =+Q13*2 -> 15000 | S13: 15000 | T13: =+R13-S13 -> 0 | V13: 1 | W13: 45805 | X13: adm | Y13: 100 | Z13: Ghora back to home | AA13: Abdul
A14: 11 | B14: Aoun Abbas | F14: 900 | H14: =+F14*2 -> 1800 | I14: 1800 | J14: =+H14-I14 -> 0 | L14: =+F14*2+J14 -> 1800 | N14: 11 | O14: Munir | P14: Comp Op | Q14: 10000 | R14: =+Q14*2 -> 20000 | S14: 20000 | T14: =+R14-S14 -> 0 | V14: 2 | Y14: =990+350+250+50+40+130+200+1130+800+110+300+150+200+130+180+120+350+180+200+130+300+100+60+200+100+0 -> 6750
A15: 12 | B15: Kubra Zahra | F15: 900 | H15: =+F15*2 -> 1800 | I15: 1800 | J15: =+H15-I15 -> 0 | L15: =+F15*2+J15 -> 1800 | N15: 12 | O15: Wajid Ali | P15: Security Guard | Q15: 8000 | R15: =+Q15*2 -> 16000 | S15: 16000 | T15: =+R15-S15 -> 0 | V15: 3 | X15: Distributed | Y15: =210000*3 -> 630000
A16: 13 | B16: M.Shuja Abbas | F16: 1750 | H16: =+F16*2 -> 3500 | I16: 3500 | J16: =+H16-I16 -> 0 | L16: =+F16*2+J16 -> 3500 | N16: 13 | O16: Sajad | P16: Sweeper | Q16: 6000 | R16: =+Q16*2 -> 12000 | S16: 12000 | T16: =+R16-S16 -> 0 | V16: 4 | W16: 45856 | X16: Repair | Y16: 7000 | Z16: Repair of washroom | AA16: Abdul
A17: 14 | B17: Anshra | F17: 900 | H17: =+F17*2 -> 1800 | I17: 1800 | J17: =+H17-I17 -> 0 | L17: =+F17*2+J17 -> 1800 | N17: Total | Q17: =SUM(Q3:Q16) -> 115500 | R17: =SUM(R3:R16) -> 231000 | S17: =SUM(S3:S16) -> 231000 | T17: =SUM(T3:T16) -> 0 | V17: 5 | W17: 45856 | X17: Repair | Y17: 1750 | Z17: Well maintenance | AA17: Abdul
A18: 15 | B18: Muhammad Safi Raza | F18: 1750 | H18: =+F18*2 -> 3500 | I18: 3500 | J18: =+H18-I18 -> 0 | L18: =+F18*2+J18 -> 3500 | V18: 6 | W18: 45859 | X18: Repair | Y18: 1000 | Z18: Paint Garder | AA18: Abdul
A19: 16 | B19: Amna Batool | F19: 1750 | H19: =+F19*2 -> 3500 | I19: 3500 | J19: =+H19-I19 -> 0 | L19: =+F19*2+J19 -> 3500 | V19: 7
A20: 17 | B20: Tawasal Zahra | F20: 1750 | H20: =+F20*2 -> 3500 | I20: 3500 | J20: =+H20-I20 -> 0 | L20: =+F20*2+J20 -> 3500 | V20: 8
A21: 18 | B21: Ashal Abbas | F21: 1750 | H21: =+F21*2 -> 3500 | I21: 3500 | J21: =+H21-I21 -> 0 | L21: =+F21*2+J21 -> 3500 | V21: 9
A22: 19 | B22: M Hannan Ali | F22: 900 | H22: =+F22*2 -> 1800 | I22: 1800 | J22: =+H22-I22 -> 0 | L22: =+F22*2+J22 -> 1800 | V22: 10
A23: 20 | B23: M Hilal | F23: 1750 | H23: =+F23*2 -> 3500 | I23: 3500 | J23: =+H23-I23 -> 0 | L23: =+F23*2+J23 -> 3500 | V23: 11
A24: 21 | B24: Hussain Abbas | F24: 1750 | H24: =+F24*2 -> 3500 | I24: 3500 | J24: =+H24-I24 -> 0 | L24: =+F24*2+J24 -> 3500 | V24: 12
A25: 22 | B25: Wajdan Hussain | F25: 1750 | H25: =+F25*2 -> 3500 | I25: 3500 | J25: =+H25-I25 -> 0 | L25: =+F25*2+J25 -> 3500
A26: 23 | B26: Komal Batool | F26: 0 | H26: =+F26*2 -> 0 | I26: 0 | J26: =+H26-I26 -> 0 | L26: =+F26*2+J26 -> 0
A27: 24 | B27: Syed Sajad Hussain | F27: 0 | H27: =+F27*2 -> 0 | I27: 0 | J27: =+H27-I27 -> 0 | L27: =+F27*2+J27 -> 0
A28: 25 | B28: Maheen | F28: 0 | H28: =+F28*2 -> 0 | I28: 0 | J28: =+H28-I28 -> 0 | L28: =+F28*2+J28 -> 0 | V28: 17
A29: 26 | B29: Muhammad Jasim | F29: 900 | H29: =+F29*2 -> 1800 | I29: 1800 | J29: =+H29-I29 -> 0 | L29: =+F29*2+J29 -> 1800 | V29: 18
A30: 27 | B30: Wadiat Zahra | F30: 1750 | H30: =+F30*2 -> 3500 | I30: 3500 | J30: =+H30-I30 -> 0 | L30: =+F30*2+J30 -> 3500 | V30: 19
A31: 28 | B31: Hoorain Zahra | F31: 1750 | H31: =+F31*2 -> 3500 | I31: 3500 | J31: =+H31-I31 -> 0 | L31: =+F31*2+J31 -> 3500 | V31: 20
A32: 29 | B32: Javed Iqbal | F32: 900 | H32: =+F32*2 -> 1800 | I32: 1800 | J32: =+H32-I32 -> 0 | L32: =+F32*2+J32 -> 1800 | V32: 21
A33: 30 | B33: M Abbas | F33: 900 | G33: =SUM(G4:G31) -> 0 | H33: =+F33*2 -> 1800 | J33: =+H33-I33 -> 1800 | L33: =+F33*2+J33 -> 3600 | V33: 22
A34: 31 | B34: Farhan Raza | F34: 900 | H34: =+F34*2 -> 1800 | I34: 1800 | J34: =+H34-I34 -> 0 | L34: =+F34*2+J34 -> 1800 | V34: 23
A35: 32 | B35: Adeel Raza | F35: 1750 | H35: =+F35*2 -> 3500 | I35: 3500 | J35: =+H35-I35 -> 0 | L35: =+F35*2+J35 -> 3500 | V35: 21
A36: Total | F36: =SUM(F4:F35) -> 37900 | H36: =SUM(H4:H35) -> 75800 | I36: =SUM(I4:I35) -> 68800 | J36: =SUM(J4:J35) -> 7000 | V36: 22
A37: Class Junior 1 | V37: 23
A38: Roll No | B38: Name | C38: Father Name | D38: Phone | E38: WA Number | F38: Monthly Fee | H38: Total Payable | I38: FEE | J38: Balance | V38: 24
A39: 1 | B39: Taimur Hussain | F39: 900 | H39: =+F39*2 -> 1800 | I39: 1800 | J39: =+H39-I39 -> 0 | L39: =+F39*2+J39 -> 1800 | V39: 25
A40: 2 | B40: Maham | F40: 900 | H40: =+F40*2 -> 1800 | I40: 1800 | J40: =+H40-I40 -> 0 | L40: =+F40*2+J40 -> 1800 | V40: 26
...

Sheet Br2 Income Exp - AugSep 25
A1: June Jul 2025 Ledger | M1: PAY ROLL - May Jun 2025
A2: PLAY GROUP | M2: S/No | N2: Name of Employee | O2: Post | P2: Pay | Q2: Total (May Jun 2025) | R2: Paid (May Jun 2025) | S2: Bal
A3: Roll No | B3: Name | C3: Father's Name | D3: Phone No | E3: WhatsApp Number | F3: Monthly fee | G3: 1500 | H3: Total Payable | I3: Fee | J3: Balance | K3: Comments | M3: 1 | N3: Mr Mureed Kazim | O3: Principal | P3: 17000 | Q3: =+P3*2 -> 34000 | R3: 34000 | S3: =+Q3-R3 -> 0 | U3: PAYMENTS | Z3: Paid By
A4: 1 | B4: Zarwa Hassan | C4: Syed Waseem Ul Hassan | F4: 1750 | H4: =+F4*2 -> 3500 | I4: 3500 | J4: =+H4-I4 -> 0 | L4: =+J4+F4*2 -> 3500 | M4: 2 | N4: Bibi Asmat Zahra | O4: JET | P4: 7400 | Q4: =+P4*2 -> 14800 | R4: 14800 | S4: =+Q4-R4 -> 0 | U4: a. | V4: Rent | X4: 34000 | Z4: Principal
A5: 2 | B5: Sughra Ali | C5: Nawazish Ali | F5: 1750 | H5: =+F5*2 -> 3500 | I5: 3500 | J5: =+H5-I5 -> 0 | L5: =+J5+F5*2 -> 3500 | M5: 3 | N5: Lubna Jaffery | O5: Asst Teacher | P5: 8000 | Q5: 15250 | R5: 15250 | S5: =+Q5-R5 -> 0 | U5: b. | V5: Elec Bill | Z5: Principal
A6: 3 | B6: Hoor Fatima | C6: Murtaza Ali | F6: 1750 | H6: =+F6*2 -> 3500 | I6: 3500 | J6: =+H6-I6 -> 0 | L6: =+J6+F6*2 -> 3500 | M6: 4 | N6: Fazila Abbas | O6: JET | P6: 8000 | Q6: =+P6*2 -> 16000 | R6: 16000 | S6: =+Q6-R6 -> 0 | U6: c. | V6: Net Pkg Staff | X6: 2000 | Z6: Principal
A7: 5 | B7: S Maisam Abbas | C7: Syed Waseem Badsha | F7: 900 | H7: =+F7*2 -> 1800 | I7: 1800 | J7: =+H7-I7 -> 0 | L7: =+J7+F7*2 -> 1800 | M7: 5 | N7: Zahra Fatima | O7: JET | P7: 6600 | Q7: =+P7*2 -> 13200 | R7: 13200 | S7: =+Q7-R7 -> 0 | U7: d.
A8: 6 | B8: Haniya Batool | C8: Jamal Khan | F8: 1750 | H8: =+F8*2 -> 3500 | I8: 3500 | J8: =+H8-I8 -> 0 | L8: =+J8+F8*2 -> 3500 | M8: 6 | N8: Kaneez Zahra | O8: JET | P8: 6600 | Q8: =+P8*2 -> 13200 | R8: 13200 | S8: =+Q8-R8 -> 0 | U8: e.
A9: 7 | B9: Adian Mehdi | C9: Rehan Ali | F9: 900 | H9: =+F9*2 -> 1800 | I9: 1800 | J9: =+H9-I9 -> 0 | L9: =+J9+F9*2 -> 1800 | M9: 7 | N9: Safia Begum | O9: JET | P9: 7800 | Q9: 14300 | R9: 14300 | S9: =+Q9-R9 -> 0 | U9: f.
A10: 8 | B10: Ashtar Abbas | C10: Azmat Ali | F10: 1750 | H10: =+F10*2 -> 3500 | I10: 3500 | J10: =+H10-I10 -> 0 | L10: =+J10+F10*2 -> 3500 | M10: 8 | N10: Zahida parween | O10: JET | P10: 6500 | Q10: =+P10*2 -> 13000 | R10: 13000 | S10: =+Q10-R10 -> 0 | U10: Total | X10: =SUM(X4:X9) -> 36000
A11: 9 | B11: Huda Muneer | C11: Muneer Abbas | F11: 1750 | H11: =+F11*2 -> 3500 | I11: 3500 | J11: =+H11-I11 -> 0 | L11: =+J11+F11*2 -> 3500 | M11: 9 | N11: Saqia Batool | O11: Asst Teacher | P11: 6000 | Q11: =+P11*2 -> 12000 | R11: 12000 | S11: =+Q11-R11 -> 0 | U11: Other Payments
A12: 10 | B12: Naimat Ali | C12: Waseem Hussain | F12: 1750 | H12: =+F12*2 -> 3500 | I12: 3500 | J12: =+H12-I12 -> 0 | L12: =+J12+F12*2 -> 3500 | M12: 10 | N12: Sunbal Bahar | O12: JET | P12: 4000 | Q12: 5000 | R12: 5000 | S12: =+Q12-R12 -> 0 | U12: S/No | V12: Dated | W12: Category | X12: Amount (Rs) | Y12: Items detail | Z12: Paid By
A13: 11 | B13: Aun Muhammad | C13: Muhammad Faraz | F13: 1750 | H13: =+F13*2 -> 3500 | I13: 3500 | J13: =+H13-I13 -> 0 | L13: =+J13+F13*2 -> 3500 | M13: 11 | N13: Hira Begum | O13: Aya | P13: 6000 | Q13: =+P13*2 -> 12000 | R13: 12000 | S13: =+Q13-R13 -> 0 | U13: 1 | V13: 45807 | W13: Adm | X13: 1000 | Y13: Fan circuit | Z13: Principal
A14: 12 | B14: Muntazir Mehdi | C14: Yaqoob Ali | F14: 1750 | H14: =+F14*2 -> 3500 | I14: 3500 | J14: =+H14-I14 -> 0 | L14: =+J14+F14*2 -> 3500 | M14: 12 | N14: Syed Shan e Haider | O14: Security | P14: 5500 | Q14: =+P14*2 -> 11000 | R14: 11000 | S14: =+Q14-R14 -> 0 | U14: 2 | V14: 45807 | W14: Adm | X14: =3000+2000+1800+1400+1400 -> 9600 | Y14: Milkpack sugar tea, Sta, Toner filling, décor, net pkg | Z14: Principal
A15: 13 | B15: Eshal Zahra | F15: 900 | H15: =+F15*2 -> 1800 | I15: 1800 | J15: =+H15-I15 -> 0 | L15: =+J15+F15*2 -> 1800 | M15: 13 | N15: Mujataba Hassan | O15: Comp Op | P15: 5000 | Q15: =+P15*2 -> 10000 | R15: 10000 | S15: =+Q15-R15 -> 0 | U15: 3
A16: 14 | B16: Hur Abbas | F16: 1750 | H16: =+F16*2 -> 3500 | I16: 3500 | J16: =+H16-I16 -> 0 | L16: =+J16+F16*2 -> 3500 | M16: Total | P16: =SUM(P3:P15) -> 94400 | Q16: =SUM(Q3:Q15) -> 183750 | R16: =SUM(R3:R15) -> 183750 | S16: =SUM(S3:S15) -> 0 | U16: 4
A17: 15 | B17: Kanwal Zahra | F17: 900 | H17: =+F17*2 -> 1800 | I17: 1800 | J17: =+H17-I17 -> 0 | L17: =+J17+F17*2 -> 1800 | U17: 5
A18: 16 | B18: Abeerah Zianab | F18: 1750 | H18: =+F18*2 -> 3500 | I18: 3500 | J18: =+H18-I18 -> 0 | L18: =+J18+F18*2 -> 3500
A19: 17 | B19: Raima Hussain | F19: 900 | H19: =+F19*2 -> 1800 | I19: 1800 | J19: =+H19-I19 -> 0 | L19: =+J19+F19*2 -> 1800
A20: 18 | B20: Fareed Askar | F20: 1750 | H20: =+F20*2 -> 3500 | I20: 3500 | J20: =+H20-I20 -> 0 | L20: =+J20+F20*2 -> 3500
A21: 19 | B21: Muhadisa Batool | F21: 900 | H21: =+F21*2 -> 1800 | I21: 1800 | J21: =+H21-I21 -> 0 | L21: =+J21+F21*2 -> 1800
A22: 20 | B22: Zakir Mehdi | F22: 1750 | H22: =+F22*2 -> 3500 | I22: 3500 | J22: =+H22-I22 -> 0 | L22: =+J22+F22*2 -> 3500
A23: 21 | B23: Qayas Mehdi | F23: 900 | H23: =+F23*2 -> 1800 | I23: 1800 | J23: =+H23-I23 -> 0 | L23: =+J23+F23*2 -> 1800 | U23: G. Total | X23: =SUM(X10:X22) -> 46600
A24: 22 | B24: Sabir Fatima | F24: 900 | H24: =+F24*2 -> 1800 | I24: 1800 | J24: =+H24-I24 -> 0 | L24: =+J24+F24*2 -> 1800
A25: 23 | B25: Daim Abbas | C25: Mutahir Ali | F25: 1750 | H25: =+F25*2 -> 3500 | I25: 3500 | J25: =+H25-I25 -> 0 | L25: =+J25+F25*2 -> 3500 | U25: Securities Returned:
A26: 24 | B26: Midhat Fatima | C26: Zeeshan Ali | F26: 1750 | H26: =+F26*2 -> 3500 | I26: 3500 | J26: =+H26-I26 -> 0 | L26: =+J26+F26*2 -> 3500 | U26: Ser | V26: Last Class Attended | W26: Remarks | X26: Amount | Y26: Name of Student
A27: 25 | B27: Fasiha Batool | C27: Ghulam Hussain | F27: 900 | H27: =+F27*2 -> 1800 | I27: 1800 | J27: =+H27-I27 -> 0 | L27: =+J27+F27*2 -> 1800 | U27: 1
A28: 26 | B28: Bali Sakina | C28: Hussain Gulab | F28: 1750 | H28: =+F28*2 -> 3500 | I28: 3500 | J28: =+H28-I28 -> 0 | L28: =+J28+F28*2 -> 3500 | U28: 2
A29: 27 | B29: Syeda Zaira Zainab | C29: Manan Hussain | F29: 1750 | H29: =+F29*2 -> 3500 | I29: 3500 | J29: =+H29-I29 -> 0 | L29: =+J29+F29*2 -> 3500 | U29: 3
A30: 28 | B30: Zain Haider | C30: Gulshad Ali | F30: 900 | H30: =+F30*2 -> 1800 | I30: 1800 | J30: =+H30-I30 -> 0 | L30: =+J30+F30*2 -> 1800 | U30: 4
A31: 29 | B31: Fakhar Mehdi | C31: Muntazir Mehdi | F31: 1750 | H31: =+F31*2 -> 3500 | I31: 3500 | J31: =+H31-I31 -> 0 | L31: =+J31+F31*2 -> 3500 | U31: 5
A32: 30 | B32: Mishal Zahra | C32: Shrafat Ali | F32: 1750 | H32: =+F32*2 -> 3500 | I32: 3500 | J32: =+H32-I32 -> 0 | L32: =+J32+F32*2 -> 3500 | U32: 6
A33: 31 | B33: Mudassir Gulab | C33: Roban Ali | F33: 900 | H33: =+F33*2 -> 1800 | I33: 1800 | J33: =+H33-I33 -> 0 | L33: =+J33+F33*2 -> 1800 | U33: 7
A34: 32 | B34: Sakeena Mehdi | C34: S.Ali Naveed Raza | F34: 900 | H34: =+F34*2 -> 1800 | I34: 1800 | J34: =+H34-I34 -> 0 | L34: =+J34+F34*2 -> 1800 | U34: 8
A35: 33 | B35: Asad | F35: 900 | H35: =+F35*2 -> 1800 | I35: 0 | J35: =+H35-I35 -> 1800 | L35: =+J35+F35*2 -> 3600 | U35: 9
A36: 34 | B36: Hamza Hussain | F36: 750 | H36: =+F36*2 -> 1500 | I36: 1500 | J36: =+H36-I36 -> 0 | L36: =+J36+F36*2 -> 1500 | U36: 10
B37: Maryam Zahra | C37: Gulzar Hussain | F37: 900 | H37: =+F37*2 -> 1800 | I37: 1800 | J37: =+H37-I37 -> 0 | L37: =+J37+F37*2 -> 1800 | U37: 11
A38: Total | F38: =SUM(F4:F37) -> 46600 | H38: =SUM(H4:H37) -> 93200 | I38: =SUM(I4:I37) -> 91400 | J38: =SUM(J4:J37) -> 1800 | U38: 12
A39: CLASS - JUNIOR 1 | U39: 13
A40: Roll No | B40: Name | C40: Father's Name | D40: Phone No | E40: WhatsApp Number | F40: Monthly fee | G40: 1500 | H40: Total Payable | I40: Fee | J40: Balance | K40: Comments
...

Sheet Expense
A1: Date | B1: Branch | C1: Category | D1: Desription | E1: Amount | F1: From Account
A2: 46022 | B2: Branch 1 | C2: Salaries | D2: Miss Anila | E2: 14500 | F2: Principal Br1
A3: 46022 | B3: Branch 1 | C3: Salaries | D3: Miss Noor Fatima | E3: 5000 | F3: Principal Br1
A4: 46022 | B4: Branch 1 | C4: Salaries | D4: Miss Shazia | E4: 8800 | F4: Principal Br1
A5: 46022 | B5: Branch 1 | C5: Salaries | D5: Miss Ume Laila | E5: 9500 | F5: Principal Br1
A6: 46022 | B6: Branch 1 | C6: Salaries | D6: Miss Safina | E6: 7000 | F6: Principal Br1
A7: 46022 | B7: Branch 1 | C7: Salaries | D7: Miss Sukaina | E7: 7500 | F7: Principal Br1
A8: 46022 | B8: Branch 1 | C8: Salaries | D8: Miss Hani | E8: 8000 | F8: Principal Br1
A9: 46022 | B9: Branch 1 | C9: Salaries | D9: Miss Nazra | E9: 8000 | F9: Principal Br1
A10: 46022 | B10: Branch 1 | C10: Salaries | D10: Miss Areesha | E10: 9000 | F10: Principal Br1
A11: 46022 | B11: Branch 1 | C11: Salaries | D11: Miss Hina | E11: 9000 | F11: Principal Br1
A12: 46022 | B12: Branch 1 | C12: Salaries | D12: Yasmeen Khala | E12: 6500 | F12: Principal Br1
A13: 46022 | B13: Branch 1 | C13: Salaries | D13: Muneer | E13: 10000 | F13: Principal Br1
... A15: 46022 | B15: Branch 1 | C15: Salaries | D15: Sajad | E15: 6000 | F15: Principal Br1
A16: 46022 | B16: Branch 1 | C16: PTCL | E16: 4100 | F16: Shah Mir
A17: 46022 | B17: Branch 1 | C17: Adm | D17: Scotch tape, Brufen, Lemon max, Sugar, gas, Gift, Plates, Kettle etc | E17: =240+130+80+50+360+635+320+2000+300+200+2200+200 -> 6715 | F17: Fund Br1
A18: 46022 | B18: Branch 1 | C18: Printer | D18: Repair of Printer by Muneer | E18: 8950 | F18: Fund Br1
A19: 46022 | B19: Branch 2 | C19: Salaries | D19: Syeda Tather Fatima | E19: =15000+1500 -> 16500 | F19: Principal Br2
A20: 46022 | B20: Branch 2 | C20: Salaries | D20: Bibi Asmat Zahra | E20: 7400 | F20: Principal Br2
A21: 46022 | B21: Branch 2 | C21: Salaries | D21: Fazila Abbas | E21: 8700 | F21: Principal Br2
A22: 46022 | B22: Branch 2 | C22: Salaries | D22: Zahra Fatima | E22: 7200 | F22: Principal Br2
A23: 46022 | B23: Branch 2 | C23: Salaries | D23: Hasrat | E23: 10000 | F23: Principal Br2
A24: 46022 | B24: Branch 2 | C24: Salaries | D24: Zahida Parveen | E24: 6500 | F24: Principal Br2
A25: 46022 | B25: Branch 2 | C25: Salaries | D25: Saqia Batool | E25: 6400 | F25: Principal Br2
A26: 46022 | B26: Branch 2 | C26: Salaries | D26: Lubna Jaffery | E26: 9500 | F26: Principal Br2
A27: 46022 | B27: Branch 2 | C27: Salaries | D27: Fiza | E27: 6000 | F27: Principal Br2
A28: 46022 | B28: Branch 2 | C28: Salaries | D28: Sania | E28: 6000 | F28: Principal Br2
A29: 46022 | B29: Branch 2 | C29: Salaries | D29: S.Shane Haider | E29: 6000 | F29: Principal Br2
A30: 46022 | B30: Branch 2 | C30: Salaries | D30: Mujtaba Hassan | E30: 7000 | F30: Principal Br2
A31: 46022 | B31: Branch 2 | C31: Salaries | D31: Hira Begum | E31: 6000 | F31: Principal Br2
A32: 46022 | B32: Branch 2 | C32: Net | D32: All Staff | E32: 2000 | F32: Principal Br2
A33: 46022 | B33: Branch 2 | C33: Rent | E33: 17000 | F33: Principal Br2
A34: 46022 | B34: Branch 1 | C34: Paper | D34: 20 paper | E34: 17000 | F34: Shah Mir
A36: 46022 | C36: Distributed | E36: 280500 | F36: Agha Guloon
A37: 46028 | B37: Branch 1 | C37: Elec | E37: 1117 | F37: Abdul Abbas
A38: 46028 | B38: Branch 1 | C38: Net | E38: 4070 | F38: Shah Mir
A39: 46029 | B39: Branch 1 | C39: Elec | E39: 1344 | F39: Abdul Abbas
A40: 46043 | B40: Branch 1 | C40: Printer | D40: Tonner, fare food | E40: 3400 | F40: Principal Br1

Sheet pivot expense
A2: 45911
A3: Row Labels | B3: Sum of Amount
A4: Adm
A5: Branch 1 | B5: 6670
A6: Branch 2 | B6: 13180
A7: Adm Total | B7: 19850
A8: Paper
A9: Branch 2 | B9: 4500
A10: Paper Total | B10: 4500
A11: Rent
A12: Branch 1 | B12: 15600
A13: Branch 2 | B13: 17000
A14: Rent Total | B14: 32600
A15: Salaries
A16: Branch 1 | B16: 115800
A17: Branch 2 | B17: 98300
A18: Salaries Total | B18: 214100
A19: (blank)
A20: (blank)
A21: (blank) Total
A22: Distributed
A23: (blank) | B23: 274050
A24: Distributed Total | B24: 274050
A25: Motor
A26: Branch 1 | B26: 2900
A27: Motor Total | B27: 2900
A28: Repair
A29: Branch 1 | B29: 1350
A30: Branch 2 | B30: 4200
A31: Repair Total | B31: 5550
A32: Elec
A33: Branch 1 | B33: 1647
A34: Branch 2 | B34: 432
A35: Elec Total | B35: 2079
A36: Net
A37: Branch 2 | B37: 2000
A38: Net Total | B38: 2000
A39: Grand Total | B39: 557629

Sheet pivot income
